# Unity协程异常捕获问题解析

## Question 1

为什么unity的携程中抛出异常，无法在外部被try捕获？

## Answer 1

在 Unity 的协程（Coroutine）中，异常无法被外部的 `try-catch` 直接捕获，这是由于协程的实现机制和 C# 迭代器（`IEnumerator`）的工作方式导致的。以下是具体原因和解决方案：

---

### **原因分析**
1. **协程的迭代器本质**  
   Unity 协程基于 C# 的 `IEnumerator` 实现。当协程中抛出异常时，异常会被封装在迭代器的 `MoveNext()` 方法中，而不会立即传播到协程的调用栈（如 `StartCoroutine` 的调用处）。因此，外部代码无法直接捕获协程内部的异常。

2. **异常的延迟抛出**  
   协程的异常会在下一次迭代时（即协程恢复执行时）被抛出。此时，外部的 `try-catch` 可能已经退出了上下文，导致无法捕获。

---

### **解决方案**
#### 1. **在协程内部捕获异常**
直接在协程内部使用 `try-catch`，确保异常在协程的作用域内处理：

```csharp
IEnumerator MyCoroutine() {
    try {
        // 可能会抛出异常的代码
        yield return new WaitForSeconds(1);
        throw new System.Exception("协程内部错误");
    } catch (System.Exception e) {
        Debug.LogError("协程内部捕获异常: " + e.Message);
    }
}
```

#### 2. **通过协程返回值传递异常**
若需要在外部处理异常，可以通过协程的返回值传递异常信息。例如，使用 `System.Action` 回调：

```csharp
IEnumerator SafeCoroutine(Action<Exception> onError) {
    try {
        // 可能会抛出异常的代码
        yield return new WaitForSeconds(1);
        throw new System.Exception("协程内部错误");
    } catch (System.Exception e) {
        onError?.Invoke(e);
    }
}

// 调用协程
StartCoroutine(SafeCoroutine(e => {
    Debug.LogError("外部捕获异常: " + e.Message);
}));
```

#### 3. **使用 `yield return` 检查协程状态**
通过 `yield return` 协程并检查其执行状态（需要手动管理协程对象）：

```csharp
IEnumerator MyCoroutine() {
    // 可能会抛出异常的代码
    yield return new WaitForSeconds(1);
    throw new System.Exception("协程内部错误");
}

// 外部调用
IEnumerator coroutine = MyCoroutine();
while (true) {
    try {
        if (!coroutine.MoveNext()) break;
    } catch (System.Exception e) {
        Debug.LogError("外部捕获异常: " + e.Message);
        break;
    }
    yield return coroutine.Current;
}
```

---

### **为什么外部 `try-catch` 无法捕获？**
以下代码是无效的，因为 `StartCoroutine` **不会同步执行协程**，异常不会直接传播到此处：

```csharp
// 错误示例：外部 try-catch 无法捕获协程异常
try {
    StartCoroutine(MyCoroutine());
} catch (System.Exception e) {
    // 此处无法捕获协程内部的异常
}
```

协程的异常会在 Unity 的主循环更新时（即下一帧）抛出，而此时外部的 `try-catch` 已经退出执行上下文。

---

### **总结**
- Unity 协程的异常处理需要**在协程内部**完成，或通过回调/返回值将异常传递到外部。
- 理解协程的异步特性是关键：异常不会立即传播到调用栈，而是延迟到协程恢复执行时抛出。

如果需要全局捕获所有未处理的协程异常，可以监听 Unity 的日志回调（`Application.logMessageReceived`），但这种方式无法恢复程序逻辑，仅适合记录错误。

## Question 2

那为什么async task就可以在外部捕获异常呢？

## Answer 2

在 C# 的 `async Task` 中，异常可以通过 `await` 关键字传播到调用栈，并能在外部通过 `try-catch` 捕获。这是因为 `async/await` 是基于 **状态机** 和 `Task` 对象实现的异步模式，与 Unity 协程（基于迭代器）的异常处理机制有本质区别。以下是具体原因和对比：

---

### **1. `async Task` 的异常传播机制**
#### **(1) 异常的封装与延迟抛出**
- 当 `async Task` 方法中抛出异常时，异常会被封装到返回的 `Task` 对象中，而不是立即抛出。
- 只有在调用 `await` 时，`Task` 中的异常才会被**解包**并重新抛出到当前的同步上下文（调用栈）。

#### **(2) 示例代码**
```csharp
async Task ThrowExceptionAsync() {
    await Task.Delay(1000);
    throw new Exception("Async 内部异常");
}

async void CallAsyncMethod() {
    try {
        await ThrowExceptionAsync(); // 异常在此处被解包并抛出
    } catch (Exception e) {
        Debug.LogError($"外部捕获异常: {e.Message}");
    }
}
```
- **关键点**：异常会在 `await` 语句处抛出，因此外部的 `try-catch` 可以捕获。

---

### **2. Unity 协程的异常处理机制**
#### **(1) 迭代器的特性**
- Unity 协程本质是通过 `IEnumerator` 实现的迭代器。协程每次通过 `yield return` 暂停后，由 Unity 引擎在主循环中调用 `MoveNext()` 恢复执行。
- 如果协程内部抛出异常，异常会直接终止迭代器，但异常会被 Unity **引擎捕获并输出到控制台**，而不会传递到 `StartCoroutine` 的调用处。

#### **(2) 示例代码**
```csharp
IEnumerator CoroutineWithException() {
    yield return new WaitForSeconds(1);
    throw new Exception("协程内部异常");
}

void Start() {
    // 外部的 try-catch 无法捕获协程异常
    try {
        StartCoroutine(CoroutineWithException());
    } catch (Exception e) {
        // 此处永远不会执行
    }
}
```
- **关键点**：协程的异常是在 Unity 主循环的 `MoveNext()` 调用中抛出的，与 `StartCoroutine` 的调用栈无关，因此外部 `try-catch` 无法捕获。

---

### **3. 核心区别**
| 特性                | `async Task`                          | Unity 协程                          |
|---------------------|---------------------------------------|-------------------------------------|
| **异常存储位置**     | 封装在 `Task` 对象中                  | 直接抛出，由 Unity 引擎捕获         |
| **异常抛出时机**     | 在 `await` 时解包并抛出               | 在迭代器 `MoveNext()` 时抛出        |
| **调用栈上下文**     | 与 `await` 的调用栈一致               | 在 Unity 主循环的上下文中抛出       |
| **外部捕获可能性**   | 可通过 `try-catch` 包裹 `await` 捕获  | 无法直接捕获                        |

---

### **4. 为什么 `async Task` 可以在外部捕获异常？**
- **`Task` 的异常延迟机制**：`async` 方法中的异常不会立即抛出，而是存储在 `Task` 对象中。只有通过 `await` 等待这个 `Task` 时，异常才会被重新抛出到当前同步上下文。
- **调用栈保留**：`async/await` 通过状态机保留了调用栈的上下文，使得异常可以沿着逻辑上的调用链传递。

---

### **5. 在 Unity 中处理 `async Task` 的异常**
如果要在 Unity 中正确捕获 `async Task` 的异常，必须使用 `await` 并包裹在 `try-catch` 中：
```csharp
async void Start() {
    try {
        await ThrowExceptionAsync();
    } catch (Exception e) {
        Debug.LogError($"外部捕获异常: {e.Message}");
    }
}
```

---

### **6. 协程的替代方案**
如果需要在协程中实现类似 `async Task` 的异常传播，可以手动封装异常信息（例如通过回调或自定义容器）：
```csharp
IEnumerator SafeCoroutine(Action<Exception> onError) {
    try {
        yield return new WaitForSeconds(1);
        throw new Exception("协程内部异常");
    } catch (Exception e) {
        onError?.Invoke(e);
    }
}

void Start() {
    StartCoroutine(SafeCoroutine(e => {
        Debug.LogError($"外部捕获异常: {e.Message}");
    }));
}
```

---

### **总结**
- **`async Task`** 的异常通过 `Task` 对象和 `await` 机制传播，保留了调用栈上下文，因此可以在外部捕获。
- **Unity 协程** 的异常由于迭代器的工作方式，由引擎直接处理，无法传递到外部调用栈。
- 若需在协程中实现类似 `async/await` 的异常处理，需手动传递异常（如回调或自定义错误处理逻辑）。
